Workbook
Name Datos: [1]!Tabla2[#Data]
Name SegmentaciónDeDatos_Almacén_Destino: #N/A
Name SegmentaciónDeDatos_Año_Pedido: #N/A
Name SegmentaciónDeDatos_Categoría: #N/A
Name SegmentaciónDeDatos_Incidencias: #N/A
Name SegmentaciónDeDatos_Modo_Transporte: #N/A
Name SegmentaciónDeDatos_Proveedor: #N/A
Name SegmentaciónDeDatos_Transportista: #N/A

Sheet Dataset Limpio
A1: ID_Pedido | B1: Fecha_Pedido | C1: Año_Pedido | D1: Mes_Pedido | E1: Semana_Pedido | F1: Proveedor | G1: Categoría | H1: Producto_SKU | I1: Almacén_Destino | J1: Transportista | K1: Modo_Transporte | L1: Incoterm | M1: Cantidad | N1: Unidad_Medida | O1: Precio_Unitario_EUR | P1: Valor_Total_EUR | Q1: Coste_Transporte_EUR | R1: Pct_Coste_Transporte | S1: Lead_Time_Días | T1: Fecha_Entrega_Estimada | U1: Fecha_Entrega_Real | V1: Desviación_Días | W1: Estado | X1: OTIF | Y1: Nivel_Stock_Inicial | Z1: Nivel_Stock_Final | AA1: Incidencias | AB1: Flag_Incidencia
A2: PED-00001 | B2: 45581 | C2: =YEAR(B2) -> 2024 | D2: =MONTH(B2) -> 10 | E2: =WEEKNUM(B2,1) -> 42 | F2: EuroDistrib S.A. | G2: Maquinaria | H2: SKU-MAQ-5395 | I2: ALM-ZGZ-01 | J2: FedEx ES | K2: Marítimo | L2: EXW | M2: 28 | N2: Metros | O2: 1212.26 | P2: 33943.28 | Q2: 1224.77 | R2: =Q2/P2 -> 0.036082842 | S2: 7 | T2: 45588 | U2: 45587 | V2: =U2-T2 -> -1 | W2: Entregado | X2: =IF(W2="Entregado", TRUE(), FALSE()) -> TRUE | Y2: 323 | Z2: 261 | AA2: Ninguna | AB2: =IF(AA2="Ninguna",FALSE(),TRUE()) -> FALSE
A3: PED-00002 | B3: 45041 | C3: =YEAR(B3) -> 2023 | D3: =MONTH(B3) -> 4 | E3: =WEEKNUM(B3,1) -> 17 | F3: FastShip Iberia | G3: Maquinaria | H3: SKU-MAQ-2522 | I3: ALM-ZGZ-01 | J3: FedEx ES | K3: Ferroviario | L3: DAP | M3: 692 | N3: Cajas | O3: 1860.55 | P3: 1287500.6 | Q3: 88435.79 | R3: =Q3/P3 -> 0.06868796 | S3: 20 | T3: 45061 | U3: 45061 | V3: =U3-T3 -> 0 | W3: Entregado | X3: =IF(W3="Entregado", TRUE(), FALSE()) -> TRUE | Y3: 301 | Z3: 486 | AA3: Error de cantidad | AB3: =IF(AA3="Ninguna",FALSE(),TRUE()) -> TRUE
A4: PED-00003 | B4: 44952 | C4: =YEAR(B4) -> 2023 | D4: =MONTH(B4) -> 1 | E4: =WEEKNUM(B4,1) -> 4 | F4: FastShip Iberia | G4: Farmacia | H4: SKU-FAR-7105 | I4: ALM-ZGZ-01 | J4: Correos Express | K4: Marítimo | L4: FCA | M4: 459 | N4: Cajas | O4: 203.36 | P4: 93342.24 | Q4: 2176.89 | R4: =Q4/P4 -> 0.023321596 | S4: 29 | T4: 44981 | U4: 44983 | V4: =U4-T4 -> 2 | W4: Retrasado | X4: =IF(W4="Entregado", TRUE(), FALSE()) -> FALSE | Y4: 368 | Z4: 453 | AA4: Pérdida parcial | AB4: =IF(AA4="Ninguna",FALSE(),TRUE()) -> TRUE
A5: PED-00004 | B5: 45208 | C5: =YEAR(B5) -> 2023 | D5: =MONTH(B5) -> 10 | E5: =WEEKNUM(B5,1) -> 41 | F5: EuroDistrib S.A. | G5: Automoción | H5: SKU-AUT-6615 | I5: ALM-ZGZ-01 | J5: Correos Express | K5: Camión LTL | L5: FCA | M5: 83 | N5: Cajas | O5: 645.13 | P5: 53545.79 | Q5: 2799.76 | R5: =Q5/P5 -> 0.052287211 | S5: 15 | T5: 45223 | U5: 45226 | V5: =U5-T5 -> 3 | W5: En almacén | X5: =IF(W5="Entregado", TRUE(), FALSE()) -> FALSE | Y5: 27 | Z5: 442 | AA5: Daño en mercancía | AB5: =IF(AA5="Ninguna",FALSE(),TRUE()) -> TRUE
A6: PED-00005 | B6: 45177 | C6: =YEAR(B6) -> 2023 | D6: =MONTH(B6) -> 9 | E6: =WEEKNUM(B6,1) -> 36 | F6: TransEuro Logistics | G6: Químicos | H6: SKU-QUÍ-3996 | I6: ALM-ZGZ-01 | J6: DHL Express | K6: Camión FTL | L6: FCA | M6: 582 | N6: KG | O6: 99.24 | P6: 57757.68 | Q6: 1399.64 | R6: =Q6/P6 -> 0.024232968 | S6: 11 | T6: 45188 | U6: 45191 | V6: =U6-T6 -> 3 | W6: En almacén | X6: =IF(W6="Entregado", TRUE(), FALSE()) -> FALSE | Y6: 484 | Z6: 261 | AA6: Pérdida parcial | AB6: =IF(AA6="Ninguna",FALSE(),TRUE()) -> TRUE
A7: PED-00006 | B7: 45155 | C7: =YEAR(B7) -> 2023 | D7: =MONTH(B7) -> 8 | E7: =WEEKNUM(B7,1) -> 33 | F7: Global Parts S.L. | G7: Textil | H7: SKU-TEX-2865 | I7: ALM-MAD-01 | J7: DHL Express | K7: Ferroviario | L7: CIF | M7: 948 | N7: Litros | O7: 87.57 | P7: 83016.36 | Q7: 6312.73 | R7: =Q7/P7 -> 0.076041999 | S7: 8 | T7: 45163 | U7: 45163 | V7: =U7-T7 -> 0 | W7: Entregado | X7: =IF(W7="Entregado", TRUE(), FALSE()) -> TRUE | Y7: 76 | Z7: 30 | AA7: Daño en mercancía | AB7: =IF(AA7="Ninguna",FALSE(),TRUE()) -> TRUE
A8: PED-00007 | B8: 45069 | C8: =YEAR(B8) -> 2023 | D8: =MONTH(B8) -> 5 | E8: =WEEKNUM(B8,1) -> 21 | F8: EuroDistrib S.A. | G8: Electrónica | H8: SKU-ELE-7566 | I8: ALM-MAD-02 | J8: MRW | K8: Ferroviario | L8: DAP | M8: 674 | N8: Unidades | O8: 701.84 | P8: 473040.16 | Q8: 31211.7 | R8: =Q8/P8 -> 0.065981079 | S8: 29 | T8: 45098 | U8: 45098 | V8: =U8-T8 -> 0 | W8: Entregado | X8: =IF(W8="Entregado", TRUE(), FALSE()) -> TRUE | Y8: 120 | Z8: 104 | AA8: Pérdida parcial | AB8: =IF(AA8="Ninguna",FALSE(),TRUE()) -> TRUE
A9: PED-00008 | B9: 45031 | C9: =YEAR(B9) -> 2023 | D9: =MONTH(B9) -> 4 | E9: =WEEKNUM(B9,1) -> 15 | F9: LogiTech Supply S.L. | G9: Maquinaria | H9: SKU-MAQ-7557 | I9: ALM-VAL-01 | J9: XPO Logistics | K9: Marítimo | L9: FCA | M9: 285 | N9: KG | O9: 2138.45 | P9: 609458.25 | Q9: 36248.75 | R9: =Q9/P9 -> 0.059477003 | S9: 21 | T9: 45052 | U9: 45049 | V9: =U9-T9 -> -3 | W9: Entregado | X9: =IF(W9="Entregado", TRUE(), FALSE()) -> TRUE | Y9: 2 | Z9: 487 | AA9: Error de cantidad | AB9: =IF(AA9="Ninguna",FALSE(),TRUE()) -> TRUE
A10: PED-00009 | B10: 45619 | C10: =YEAR(B10) -> 2024 | D10: =MONTH(B10) -> 11 | E10: =WEEKNUM(B10,1) -> 47 | F10: Iberian Freight Co. | G10: Construcción | H10: SKU-CON-8479 | I10: ALM-BCN-01 | J10: MRW | K10: Aéreo | L10: DDP | M10: 57 | N10: KG | O10: 298.65 | P10: 17023.05 | Q10: 1181.97 | R10: =Q10/P10 -> 0.069433503 | S10: 7 | T10: 45626 | U10: 45634 | V10: =U10-T10 -> 8 | W10: Retrasado | X10: =IF(W10="Entregado", TRUE(), FALSE()) -> FALSE | Y10: 36 | Z10: 349 | AA10: Documentación incompleta | AB10: =IF(AA10="Ninguna",FALSE(),TRUE()) -> TRUE
A11: PED-00010 | B11: 45485 | C11: =YEAR(B11) -> 2024 | D11: =MONTH(B11) -> 7 | E11: =WEEKNUM(B11,1) -> 28 | F11: MadridPack S.A. | G11: Construcción | H11: SKU-CON-5453 | I11: ALM-ZGZ-01 | J11: MRW | K11: Aéreo | L11: DDP | M11: 220 | N11: KG | O11: 173.33 | P11: 38132.6 | Q11: 2244.15 | R11: =Q11/P11 -> 0.058851219 | S11: 26 | T11: 45511 | U11: 45514 | V11: =U11-T11 -> 3 | W11: En almacén | X11: =IF(W11="Entregado", TRUE(), FALSE()) -> FALSE | Y11: 431 | Z11: 311 | AA11: Daño en mercancía | AB11: =IF(AA11="Ninguna",FALSE(),TRUE()) -> TRUE
A12: PED-00011 | B12: 45016 | C12: =YEAR(B12) -> 2023 | D12: =MONTH(B12) -> 3 | E12: =WEEKNUM(B12,1) -> 13 | F12: PenínsulaLogis | G12: Químicos | H12: SKU-QUÍ-7319 | I12: ALM-MAD-01 | J12: SEUR | K12: Camión LTL | L12: DAP | M12: 864 | N12: Metros | O12: 118.12 | P12: 102055.68 | Q12: 7974.29 | R12: =Q12/P12 -> 0.07813666 | S12: 19 | T12: 45035 | U12: 45037 | V12: =U12-T12 -> 2 | W12: Retrasado | X12: =IF(W12="Entregado", TRUE(), FALSE()) -> FALSE | Y12: 146 | Z12: 437 | AA12: Documentación incompleta | AB12: =IF(AA12="Ninguna",FALSE(),TRUE()) -> TRUE
A13: PED-00012 | B13: 45531 | C13: =YEAR(B13) -> 2024 | D13: =MONTH(B13) -> 8 | E13: =WEEKNUM(B13,1) -> 35 | F13: Valencia Port Traders | G13: Textil | H13: SKU-TEX-8835 | I13: ALM-VAL-01 | J13: FedEx ES | K13: Camión FTL | L13: FCA | M13: 929 | N13: Unidades | O13: 74.12 | P13: 68857.48 | Q13: 4326.83 | R13: =Q13/P13 -> 0.062837472 | S13: 23 | T13: 45554 | U13: 45553 | V13: =U13-T13 -> -1 | W13: Entregado | X13: =IF(W13="Entregado", TRUE(), FALSE()) -> TRUE | Y13: 91 | Z13: 468 | AA13: Ninguna | AB13: =IF(AA13="Ninguna",FALSE(),TRUE()) -> FALSE
... A2001: PED-02000 | B2001: 45467 | C2001: =YEAR(B2001) -> 2024 | D2001: =MONTH(B2001) -> 6 | E2001: =WEEKNUM(B2001,1) -> 26 | F2001: PenínsulaLogis | G2001: Automoción | H2001: SKU-AUT-2387 | I2001: ALM-SEV-01 | J2001: SEUR | K2001: Camión LTL | L2001: EXW | M2001: 671 | N2001: Litros | O2001: 1167.23 | P2001: 783211.33 | Q2001: 28370.26 | R2001: =Q2001/P2001 -> 0.036222995 | S2001: 3 | T2001: 45470 | U2001: 45470 | V2001: =U2001-T2001 -> 0 | W2001: Entregado | X2001: =IF(W2001="Entregado", TRUE(), FALSE()) -> TRUE | Y2001: 282 | Z2001: 58 | AA2001: Error de cantidad | AB2001: =IF(AA2001="Ninguna",FALSE(),TRUE()) -> TRUE

Sheet Análisis Descriptivo
B2: 📊 ANÁLISIS DESCRIPTIVO — SUPPLY CHAIN
B4: 1 · RESUMEN EJECUTIVO
B5: Total pedidos | D5: Valor total pedidos (€) | F5: Coste total transporte (€) | H5: % Coste transp. / Valor
B6: =COUNTA('Dataset Limpio'!A2:A2001) -> 2000 | D6: =SUM('Dataset Limpio'!P2:P2001) -> 5.0228016e+08 | F6: =SUM('Dataset Limpio'!Q2:Q2001) -> 25014696 | H6: =SUM('Dataset Limpio'!Q2:Q2001)/SUM('Dataset Limpio'!P2:P2001) -> 0.049802278
B7: OTIF global | D7: % Pedidos retrasados | F7: % Pedidos con incidencia | H7: Lead time medio global (días)
B8: =COUNTIF('Dataset Limpio'!X2:X2001,"VERDADERO")/COUNTA('Dataset Limpio'!A2:A2001) -> 0.485 | D8: =COUNTIF('Dataset Limpio'!W2:W2001,"Retrasado")/COUNTA('Dataset Limpio'!A2:A2001) -> 0.265 | F8: =COUNTIF('Dataset Limpio'!AB2:AB2001,"VERDADERO")/COUNTA('Dataset Limpio'!A2:A2001) -> 0.5765 | H8: =AVERAGE('Dataset Limpio'!S2:S2001) -> 15.1155
B11: 2 · ESTADÍSTICAS DESCRIPTIVAS — VARIABLES NUMÉRICAS
B12: Variable | C12: Mínimo | D12: Máximo | E12: Media | F12: Mediana | G12: Desv. Típica | H12: Percentil 25 | I12: Percentil 75
B13: Valor_Total_EUR | C13: =MIN('Dataset Limpio'!P2:P2001) -> 3302.8089 | D13: =MAX('Dataset Limpio'!P2:P2001) -> 1639255.4 | E13: =AVERAGE('Dataset Limpio'!P2:P2001) -> 251140.08 | F13: =MEDIAN('Dataset Limpio'!P2:P2001) -> 107129.73 | G13: =STDEV('Dataset Limpio'!P2:P2001) -> 341334.27 | H13: =PERCENTILE('Dataset Limpio'!P2:P2001,0.25) -> 42362.84 | I13: =PERCENTILE('Dataset Limpio'!P2:P2001,0.75) -> 307872.55
B14: Coste_Transporte_EUR | C14: =MIN('Dataset Limpio'!Q2:Q2001) -> 142.3601 | D14: =MAX('Dataset Limpio'!Q2:Q2001) -> 96548.63 | E14: =AVERAGE('Dataset Limpio'!Q2:Q2001) -> 12507.348 | F14: =MEDIAN('Dataset Limpio'!Q2:Q2001) -> 4822.05 | G14: =STDEV('Dataset Limpio'!Q2:Q2001) -> 18336.37 | H14: =PERCENTILE('Dataset Limpio'!Q2:Q2001,0.25) -> 1904.9825 | I14: =PERCENTILE('Dataset Limpio'!Q2:Q2001,0.75) -> 14163.815
B15: Lead_Time_Días | C15: =MIN('Dataset Limpio'!S2:S2001) -> 1 | D15: =MAX('Dataset Limpio'!S2:S2001) -> 29 | E15: =AVERAGE('Dataset Limpio'!S2:S2001) -> 15.1155 | F15: =MEDIAN('Dataset Limpio'!S2:S2001) -> 15 | G15: =STDEV('Dataset Limpio'!S2:S2001) -> 8.5583165 | H15: =PERCENTILE('Dataset Limpio'!S2:S2001,0.25) -> 8 | I15: =PERCENTILE('Dataset Limpio'!S2:S2001,0.75) -> 23
B16: Desviación_Días | C16: =MIN('Dataset Limpio'!V2:V2001) -> -5 | D16: =MAX('Dataset Limpio'!V2:V2001) -> 12 | E16: =AVERAGE('Dataset Limpio'!V2:V2001) -> 1.97 | F16: =MEDIAN('Dataset Limpio'!V2:V2001) -> 0 | G16: =STDEV('Dataset Limpio'!V2:V2001) -> 4.5207653 | H16: =PERCENTILE('Dataset Limpio'!V2:V2001,0.25) -> 0 | I16: =PERCENTILE('Dataset Limpio'!V2:V2001,0.75) -> 3
B17: Cantidad | C17: =MIN('Dataset Limpio'!M2:M2001) -> 10 | D17: =MAX('Dataset Limpio'!M2:M2001) -> 998 | E17: =AVERAGE('Dataset Limpio'!M2:M2001) -> 514.352 | F17: =MEDIAN('Dataset Limpio'!M2:M2001) -> 505.5 | G17: =STDEV('Dataset Limpio'!M2:M2001) -> 289.7572 | H17: =PERCENTILE('Dataset Limpio'!M2:M2001,0.25) -> 258.75 | I17: =PERCENTILE('Dataset Limpio'!M2:M2001,0.75) -> 771.25
B18: Precio_Unitario_EUR | C18: =MIN('Dataset Limpio'!O2:O2001) -> 42.03 | D18: =MAX('Dataset Limpio'!O2:O2001) -> 2235.75 | E18: =AVERAGE('Dataset Limpio'!O2:O2001) -> 485.90731 | F18: =MEDIAN('Dataset Limpio'!O2:O2001) -> 221.665 | G18: =STDEV('Dataset Limpio'!O2:O2001) -> 542.49147 | H18: =PERCENTILE('Dataset Limpio'!O2:O2001,0.25) -> 109.5075 | I18: =PERCENTILE('Dataset Limpio'!O2:O2001,0.75) -> 672.275
B19: Pct_Coste_Transporte | C19: =MIN('Dataset Limpio'!R2:R2001) -> 0.020014464 | D19: =MAX('Dataset Limpio'!R2:R2001) -> 0.079952419 | E19: =AVERAGE('Dataset Limpio'!R2:R2001) -> 0.049084173 | F19: =MEDIAN('Dataset Limpio'!R2:R2001) -> 0.048584308 | G19: =STDEV('Dataset Limpio'!R2:R2001) -> 0.01702097 | H19: =PERCENTILE('Dataset Limpio'!R2:R2001,0.25) -> 0.034479402 | I19: =PERCENTILE('Dataset Limpio'!R2:R2001,0.75) -> 0.063226021
B20: Nivel_Stock_Inicial | C20: =MIN('Dataset Limpio'!Y2:Y2001) -> 0 | D20: =MAX('Dataset Limpio'!Y2:Y2001) -> 499 | E20: =AVERAGE('Dataset Limpio'!Y2:Y2001) -> 250.5745 | F20: =MEDIAN('Dataset Limpio'!Y2:Y2001) -> 252 | G20: =STDEV('Dataset Limpio'!Y2:Y2001) -> 145.65722 | H20: =PERCENTILE('Dataset Limpio'!Y2:Y2001,0.25) -> 125 | I20: =PERCENTILE('Dataset Limpio'!Y2:Y2001,0.75) -> 377
B21: Nivel_Stock_Final | C21: =MIN('Dataset Limpio'!Z2:Z2001) -> 0 | D21: =MAX('Dataset Limpio'!Z2:Z2001) -> 499 | E21: =AVERAGE('Dataset Limpio'!Z2:Z2001) -> 253.784 | F21: =MEDIAN('Dataset Limpio'!Z2:Z2001) -> 258 | G21: =STDEV('Dataset Limpio'!Z2:Z2001) -> 145.83048 | H21: =PERCENTILE('Dataset Limpio'!Z2:Z2001,0.25) -> 124 | I21: =PERCENTILE('Dataset Limpio'!Z2:Z2001,0.75) -> 382
B23: 3 · ANÁLISIS POR CATEGORÍA
B24: Categoría | C24: Nº Pedidos | D24: % s/Total | E24: Valor Total (€) | F24: % Valor s/Total | G24: Coste Transp. (€) | H24: OTIF (%) | I24: Lead Time Medio | J24: % Incidencias
B25: Maquinaria | C25: =COUNTIF('Dataset Limpio'!G2:G2001,"Maquinaria") -> 266 | D25: =COUNTIF('Dataset Limpio'!G2:G2001,"Maquinaria")/COUNTA('Dataset Limpio'!A2:A2001) -> 0.133 | E25: =SUMIF('Dataset Limpio'!G2:G2001,"Maquinaria",'Dataset Limpio'!P2:P2001) -> 2.2323998e+08 | F25: =SUMIF('Dataset Limpio'!G2:G2001,"Maquinaria",'Dataset Limpio'!P2:P2001)/SUM('Dataset Limpio'!P2:P2001) -> 0.44445311 | G25: =SUMIF('Dataset Limpio'!G2:G2001,"Maquinaria",'Dataset Limpio'!Q2:Q2001) -> 11030531 | H25: =IFERROR(COUNTIFS('Dataset Limpio'!G2:G2001,"Maquinaria",'Dataset Limpio'!X2:X2001,"VERDADERO")/COUNTIF('Dataset Limpio'!G2:G2001,"Maquinaria"),0) -> 0.5037594 | I25: =AVERAGEIF('Dataset Limpio'!G2:G2001,"Maquinaria",'Dataset Limpio'!S2:S2001) -> 15.909774 | J25: =IFERROR(COUNTIFS('Dataset Limpio'!G2:G2001,"Maquinaria",'Dataset Limpio'!AB2:AB2001,"VERDADERO")/COUNTIF('Dataset Limpio'!G2:G2001,"Maquinaria"),0) -> 0.56390977
B26: Automoción | C26: =COUNTIF('Dataset Limpio'!G2:G2001,"Automoción") -> 238 | D26: =COUNTIF('Dataset Limpio'!G2:G2001,"Automoción")/COUNTA('Dataset Limpio'!A2:A2001) -> 0.119 | E26: =SUMIF('Dataset Limpio'!G2:G2001,"Automoción",'Dataset Limpio'!P2:P2001) -> 1.0873895e+08 | F26: =SUMIF('Dataset Limpio'!G2:G2001,"Automoción",'Dataset Limpio'!P2:P2001)/SUM('Dataset Limpio'!P2:P2001) -> 0.21649063 | G26: =SUMIF('Dataset Limpio'!G2:G2001,"Automoción",'Dataset Limpio'!Q2:Q2001) -> 5616697 | H26: =IFERROR(COUNTIFS('Dataset Limpio'!G2:G2001,"Automoción",'Dataset Limpio'!X2:X2001,"VERDADERO")/COUNTIF('Dataset Limpio'!G2:G2001,"Automoción"),0) -> 0.45378151 | I26: =AVERAGEIF('Dataset Limpio'!G2:G2001,"Automoción",'Dataset Limpio'!S2:S2001) -> 15.201681 | J26: =IFERROR(COUNTIFS('Dataset Limpio'!G2:G2001,"Automoción",'Dataset Limpio'!AB2:AB2001,"VERDADERO")/COUNTIF('Dataset Limpio'!G2:G2001,"Automoción"),0) -> 0.56722689
B27: Electrónica | C27: =COUNTIF('Dataset Limpio'!G2:G2001,"Electrónica") -> 262 | D27: =COUNTIF('Dataset Limpio'!G2:G2001,"Electrónica")/COUNTA('Dataset Limpio'!A2:A2001) -> 0.131 | E27: =SUMIF('Dataset Limpio'!G2:G2001,"Electrónica",'Dataset Limpio'!P2:P2001) -> 77619395 | F27: =SUMIF('Dataset Limpio'!G2:G2001,"Electrónica",'Dataset Limpio'!P2:P2001)/SUM('Dataset Limpio'!P2:P2001) -> 0.15453407 | G27: =SUMIF('Dataset Limpio'!G2:G2001,"Electrónica",'Dataset Limpio'!Q2:Q2001) -> 3855910.5 | H27: =IFERROR(COUNTIFS('Dataset Limpio'!G2:G2001,"Electrónica",'Dataset Limpio'!X2:X2001,"VERDADERO")/COUNTIF('Dataset Limpio'!G2:G2001,"Electrónica"),0) -> 0.48854962 | I27: =AVERAGEIF('Dataset Limpio'!G2:G2001,"Electrónica",'Dataset Limpio'!S2:S2001) -> 14.961832 | J27: =IFERROR(COUNTIFS('Dataset Limpio'!G2:G2001,"Electrónica",'Dataset Limpio'!AB2:AB2001,"VERDADERO")/COUNTIF('Dataset Limpio'!G2:G2001,"Electrónica"),0) -> 0.57251908
B28: Alimentación | C28: =COUNTIF('Dataset Limpio'!G2:G2001,"Alimentación") -> 235 | D28: =COUNTIF('Dataset Limpio'!G2:G2001,"Alimentación")/COUNTA('Dataset Limpio'!A2:A2001) -> 0.1175 | E28: =SUMIF('Dataset Limpio'!G2:G2001,"Alimentación",'Dataset Limpio'!P2:P2001) -> 10687789 | F28: =SUMIF('Dataset Limpio'!G2:G2001,"Alimentación",'Dataset Limpio'!P2:P2001)/SUM('Dataset Limpio'!P2:P2001) -> 0.021278542 | G28: =SUMIF('Dataset Limpio'!G2:G2001,"Alimentación",'Dataset Limpio'!Q2:Q2001) -> 522883.59 | H28: =IFERROR(COUNTIFS('Dataset Limpio'!G2:G2001,"Alimentación",'Dataset Limpio'!X2:X2001,"VERDADERO")/COUNTIF('Dataset Limpio'!G2:G2001,"Alimentación"),0) -> 0.4893617 | I28: =AVERAGEIF('Dataset Limpio'!G2:G2001,"Alimentación",'Dataset Limpio'!S2:S2001) -> 15.744681 | J28: =IFERROR(COUNTIFS('Dataset Limpio'!G2:G2001,"Alimentación",'Dataset Limpio'!AB2:AB2001,"VERDADERO")/COUNTIF('Dataset Limpio'!G2:G2001,"Alimentación"),0) -> 0.63404255
B29: Farmacia | C29: =COUNTIF('Dataset Limpio'!G2:G2001,"Farmacia") -> 269 | D29: =COUNTIF('Dataset Limpio'!G2:G2001,"Farmacia")/COUNTA('Dataset Limpio'!A2:A2001) -> 0.1345 | E29: =SUMIF('Dataset Limpio'!G2:G2001,"Farmacia",'Dataset Limpio'!P2:P2001) -> 30309925 | F29: =SUMIF('Dataset Limpio'!G2:G2001,"Farmacia",'Dataset Limpio'!P2:P2001)/SUM('Dataset Limpio'!P2:P2001) -> 0.06034466 | G29: =SUMIF('Dataset Limpio'!G2:G2001,"Farmacia",'Dataset Limpio'!Q2:Q2001) -> 1438830.6 | H29: =IFERROR(COUNTIFS('Dataset Limpio'!G2:G2001,"Farmacia",'Dataset Limpio'!X2:X2001,"VERDADERO")/COUNTIF('Dataset Limpio'!G2:G2001,"Farmacia"),0) -> 0.45724907 | I29: =AVERAGEIF('Dataset Limpio'!G2:G2001,"Farmacia",'Dataset Limpio'!S2:S2001) -> 14.486989 | J29: =IFERROR(COUNTIFS('Dataset Limpio'!G2:G2001,"Farmacia",'Dataset Limpio'!AB2:AB2001,"VERDADERO")/COUNTIF('Dataset Limpio'!G2:G2001,"Farmacia"),0) -> 0.57620818
B30: Químicos | C30: =COUNTIF('Dataset Limpio'!G2:G2001,"Químicos") -> 243 | D30: =COUNTIF('Dataset Limpio'!G2:G2001,"Químicos")/COUNTA('Dataset Limpio'!A2:A2001) -> 0.1215 | E30: =SUMIF('Dataset Limpio'!G2:G2001,"Químicos",'Dataset Limpio'!P2:P2001) -> 16057312 | F30: =SUMIF('Dataset Limpio'!G2:G2001,"Químicos",'Dataset Limpio'!P2:P2001)/SUM('Dataset Limpio'!P2:P2001) -> 0.031968837 | G30: =SUMIF('Dataset Limpio'!G2:G2001,"Químicos",'Dataset Limpio'!Q2:Q2001) -> 802542.35 | H30: =IFERROR(COUNTIFS('Dataset Limpio'!G2:G2001,"Químicos",'Dataset Limpio'!X2:X2001,"VERDADERO")/COUNTIF('Dataset Limpio'!G2:G2001,"Químicos"),0) -> 0.53497942 | I30: =AVERAGEIF('Dataset Limpio'!G2:G2001,"Químicos",'Dataset Limpio'!S2:S2001) -> 15.563786 | J30: =IFERROR(COUNTIFS('Dataset Limpio'!G2:G2001,"Químicos",'Dataset Limpio'!AB2:AB2001,"VERDADERO")/COUNTIF('Dataset Limpio'!G2:G2001,"Químicos"),0) -> 0.5308642
B31: Construcción | C31: =COUNTIF('Dataset Limpio'!G2:G2001,"Construcción") -> 249 | D31: =COUNTIF('Dataset Limpio'!G2:G2001,"Construcción")/COUNTA('Dataset Limpio'!A2:A2001) -> 0.1245 | E31: =SUMIF('Dataset Limpio'!G2:G2001,"Construcción",'Dataset Limpio'!P2:P2001) -> 27974410 | F31: =SUMIF('Dataset Limpio'!G2:G2001,"Construcción",'Dataset Limpio'!P2:P2001)/SUM('Dataset Limpio'!P2:P2001) -> 0.055694834 | G31: =SUMIF('Dataset Limpio'!G2:G2001,"Construcción",'Dataset Limpio'!Q2:Q2001) -> 1375369.3 | H31: =IFERROR(COUNTIFS('Dataset Limpio'!G2:G2001,"Construcción",'Dataset Limpio'!X2:X2001,"VERDADERO")/COUNTIF('Dataset Limpio'!G2:G2001,"Construcción"),0) -> 0.4939759 | I31: =AVERAGEIF('Dataset Limpio'!G2:G2001,"Construcción",'Dataset Limpio'!S2:S2001) -> 14.819277 | J31: =IFERROR(COUNTIFS('Dataset Limpio'!G2:G2001,"Construcción",'Dataset Limpio'!AB2:AB2001,"VERDADERO")/COUNTIF('Dataset Limpio'!G2:G2001,"Construcción"),0) -> 0.55823293
B32: Textil | C32: =COUNTIF('Dataset Limpio'!G2:G2001,"Textil") -> 238 | D32: =COUNTIF('Dataset Limpio'!G2:G2001,"Textil")/COUNTA('Dataset Limpio'!A2:A2001) -> 0.119 | E32: =SUMIF('Dataset Limpio'!G2:G2001,"Textil",'Dataset Limpio'!P2:P2001) -> 7652403 | F32: =SUMIF('Dataset Limpio'!G2:G2001,"Textil",'Dataset Limpio'!P2:P2001)/SUM('Dataset Limpio'!P2:P2001) -> 0.015235328 | G32: =SUMIF('Dataset Limpio'!G2:G2001,"Textil",'Dataset Limpio'!Q2:Q2001) -> 371931.34 | H32: =IFERROR(COUNTIFS('Dataset Limpio'!G2:G2001,"Textil",'Dataset Limpio'!X2:X2001,"VERDADERO")/COUNTIF('Dataset Limpio'!G2:G2001,"Textil"),0) -> 0.45798319 | I32: =AVERAGEIF('Dataset Limpio'!G2:G2001,"Textil",'Dataset Limpio'!S2:S2001) -> 14.252101 | J32: =IFERROR(COUNTIFS('Dataset Limpio'!G2:G2001,"Textil",'Dataset Limpio'!AB2:AB2001,"VERDADERO")/COUNTIF('Dataset Limpio'!G2:G2001,"Textil"),0) -> 0.61344538
B33: TOTAL | C33: =COUNTA('Dataset Limpio'!A2:A2001) -> 2000 | D33: =1 -> 1 | E33: =SUM('Dataset Limpio'!P2:P2001) -> 5.0228016e+08 | F33: =1 -> 1 | G33: =SUM('Dataset Limpio'!Q2:Q2001) -> 25014696 | H33: =COUNTIF('Dataset Limpio'!X2:X2001,"VERDADERO")/COUNTA('Dataset Limpio'!A2:A2001) -> 0.485 | I33: =AVERAGE('Dataset Limpio'!S2:S2001) -> 15.1155 | J33: =COUNTIF('Dataset Limpio'!AB2:AB2001,"VERDADERO")/COUNTA('Dataset Limpio'!A2:A2001) -> 0.5765
B35: 4 · ANÁLISIS POR PROVEEDOR
B36: Proveedor | C36: Nº Pedidos | D36: Valor Total (€) | E36: OTIF (%) | F36: Desv. Media (días) | G36: % Incidencias | H36: Lead Time Medio | I36: Coste Transp. (€) | J36: % Coste/Valor
B37: Valencia Port Traders | C37: =COUNTIF('Dataset Limpio'!F2:F2001,"Valencia Port Traders") -> 209 | D37: =SUMIF('Dataset Limpio'!F2:F2001,"Valencia Port Traders",'Dataset Limpio'!P2:P2001) -> 57066672 | E37: =IFERROR(COUNTIFS('Dataset Limpio'!F2:F2001,"Valencia Port Traders",'Dataset Limpio'!X2:X2001,"VERDADERO")/COUNTIF('Dataset Limpio'!F2:F2001,"Valencia Port Traders"),0) -> 0.50239234 | F37: =AVERAGEIF('Dataset Limpio'!F2:F2001,"Valencia Port Traders",'Dataset Limpio'!V2:V2001) -> 1.784689 | G37: =IFERROR(COUNTIFS('Dataset Limpio'!F2:F2001,"Valencia Port Traders",'Dataset Limpio'!AB2:AB2001,"VERDADERO")/COUNTIF('Dataset Limpio'!F2:F2001,"Valencia Port Traders"),0) -> 0.55023923 | H37: =AVERAGEIF('Dataset Limpio'!F2:F2001,"Valencia Port Traders",'Dataset Limpio'!S2:S2001) -> 14.899522 | I37: =SUMIF('Dataset Limpio'!F2:F2001,"Valencia Port Traders",'Dataset Limpio'!Q2:Q2001) -> 2928631.5 | J37: =IFERROR(SUMIF('Dataset Limpio'!F2:F2001,"Valencia Port Traders",'Dataset Limpio'!Q2:Q2001)/SUMIF('Dataset Limpio'!F2:F2001,"Valencia Port Traders",'Dataset Limpio'!P2:P2001),0) -> 0.051319471
B38: LogiTech Supply S.L. | C38: =COUNTIF('Dataset Limpio'!F2:F2001,"LogiTech Supply S.L.") -> 195 | D38: =SUMIF('Dataset Limpio'!F2:F2001,"LogiTech Supply S.L.",'Dataset Limpio'!P2:P2001) -> 56835060 | E38: =IFERROR(COUNTIFS('Dataset Limpio'!F2:F2001,"LogiTech Supply S.L.",'Dataset Limpio'!X2:X2001,"VERDADERO")/COUNTIF('Dataset Limpio'!F2:F2001,"LogiTech Supply S.L."),0) -> 0.4974359 | F38: =AVERAGEIF('Dataset Limpio'!F2:F2001,"LogiTech Supply S.L.",'Dataset Limpio'!V2:V2001) -> 1.7128205 | G38: =IFERROR(COUNTIFS('Dataset Limpio'!F2:F2001,"LogiTech Supply S.L.",'Dataset Limpio'!AB2:AB2001,"VERDADERO")/COUNTIF('Dataset Limpio'!F2:F2001,"LogiTech Supply S.L."),0) -> 0.61025641 | H38: =AVERAGEIF('Dataset Limpio'!F2:F2001,"LogiTech Supply S.L.",'Dataset Limpio'!S2:S2001) -> 14.912821 | I38: =SUMIF('Dataset Limpio'!F2:F2001,"LogiTech Supply S.L.",'Dataset Limpio'!Q2:Q2001) -> 2979690.9 | J38: =IFERROR(SUMIF('Dataset Limpio'!F2:F2001,"LogiTech Supply S.L.",'Dataset Limpio'!Q2:Q2001)/SUMIF('Dataset Limpio'!F2:F2001,"LogiTech Supply S.L.",'Dataset Limpio'!P2:P2001),0) -> 0.052426986
B39: FastShip Iberia | C39: =COUNTIF('Dataset Limpio'!F2:F2001,"FastShip Iberia") -> 225 | D39: =SUMIF('Dataset Limpio'!F2:F2001,"FastShip Iberia",'Dataset Limpio'!P2:P2001) -> 53031676 | E39: =IFERROR(COUNTIFS('Dataset Limpio'!F2:F2001,"FastShip Iberia",'Dataset Limpio'!X2:X2001,"VERDADERO")/COUNTIF('Dataset Limpio'!F2:F2001,"FastShip Iberia"),0) -> 0.52 | F39: =AVERAGEIF('Dataset Limpio'!F2:F2001,"FastShip Iberia",'Dataset Limpio'!V2:V2001) -> 1.5866667 | G39: =IFERROR(COUNTIFS('Dataset Limpio'!F2:F2001,"FastShip Iberia",'Dataset Limpio'!AB2:AB2001,"VERDADERO")/COUNTIF('Dataset Limpio'!F2:F2001,"FastShip Iberia"),0) -> 0.51555556 | H39: =AVERAGEIF('Dataset Limpio'!F2:F2001,"FastShip Iberia",'Dataset Limpio'!S2:S2001) -> 14.782222 | I39: =SUMIF('Dataset Limpio'!F2:F2001,"FastShip Iberia",'Dataset Limpio'!Q2:Q2001) -> 2588353.1 | J39: =IFERROR(SUMIF('Dataset Limpio'!F2:F2001,"FastShip Iberia",'Dataset Limpio'!Q2:Q2001)/SUMIF('Dataset Limpio'!F2:F2001,"FastShip Iberia",'Dataset Limpio'!P2:P2001),0) -> 0.048807681
B40: EuroDistrib S.A. | C40: =COUNTIF('Dataset Limpio'!F2:F2001,"EuroDistrib S.A.") -> 199 | D40: =SUMIF('Dataset Limpio'!F2:F2001,"EuroDistrib S.A.",'Dataset Limpio'!P2:P2001) -> 48391808 | E40: =IFERROR(COUNTIFS('Dataset Limpio'!F2:F2001,"EuroDistrib S.A.",'Dataset Limpio'!X2:X2001,"VERDADERO")/COUNTIF('Dataset Limpio'!F2:F2001,"EuroDistrib S.A."),0) -> 0.53768844 | F40: =AVERAGEIF('Dataset Limpio'!F2:F2001,"EuroDistrib S.A.",'Dataset Limpio'!V2:V2001) -> 1.9246231 | G40: =IFERROR(COUNTIFS('Dataset Limpio'!F2:F2001,"EuroDistrib S.A.",'Dataset Limpio'!AB2:AB2001,"VERDADERO")/COUNTIF('Dataset Limpio'!F2:F2001,"EuroDistrib S.A."),0) -> 0.61306533 | H40: =AVERAGEIF('Dataset Limpio'!F2:F2001,"EuroDistrib S.A.",'Dataset Limpio'!S2:S2001) -> 14.643216 | I40: =SUMIF('Dataset Limpio'!F2:F2001,"EuroDistrib S.A.",'Dataset Limpio'!Q2:Q2001) -> 2395368.3 | J40: =IFERROR(SUMIF('Dataset Limpio'!F2:F2001,"EuroDistrib S.A.",'Dataset Limpio'!Q2:Q2001)/SUMIF('Dataset Limpio'!F2:F2001,"EuroDistrib S.A.",'Dataset Limpio'!P2:P2001),0) -> 0.049499458
B41: PenínsulaLogis | C41: =COUNTIF('Dataset Limpio'!F2:F2001,"PenínsulaLogis") -> 206 | D41: =SUMIF('Dataset Limpio'!F2:F2001,"PenínsulaLogis",'Dataset Limpio'!P2:P2001) -> 49119204 | E41: =IFERROR(COUNTIFS('Dataset Limpio'!F2:F2001,"PenínsulaLogis",'Dataset Limpio'!X2:X2001,"VERDADERO")/COUNTIF('Dataset Limpio'!F2:F2001,"PenínsulaLogis"),0) -> 0.52427184 | F41: =AVERAGEIF('Dataset Limpio'!F2:F2001,"PenínsulaLogis",'Dataset Limpio'!V2:V2001) -> 1.7475728 | G41: =IFERROR(COUNTIFS('Dataset Limpio'!F2:F2001,"PenínsulaLogis",'Dataset Limpio'!AB2:AB2001,"VERDADERO")/COUNTIF('Dataset Limpio'!F2:F2001,"PenínsulaLogis"),0) -> 0.56796117 | H41: =AVERAGEIF('Dataset Limpio'!F2:F2001,"PenínsulaLogis",'Dataset Limpio'!S2:S2001) -> 16.15534 | I41: =SUMIF('Dataset Limpio'!F2:F2001,"PenínsulaLogis",'Dataset Limpio'!Q2:Q2001) -> 2311265.2 | J41: =IFERROR(SUMIF('Dataset Limpio'!F2:F2001,"PenínsulaLogis",'Dataset Limpio'!Q2:Q2001)/SUMIF('Dataset Limpio'!F2:F2001,"PenínsulaLogis",'Dataset Limpio'!P2:P2001),0) -> 0.047054206
B42: MadridPack S.A. | C42: =COUNTIF('Dataset Limpio'!F2:F2001,"MadridPack S.A.") -> 195 | D42: =SUMIF('Dataset Limpio'!F2:F2001,"MadridPack S.A.",'Dataset Limpio'!P2:P2001) -> 48891141 | E42: =IFERROR(COUNTIFS('Dataset Limpio'!F2:F2001,"MadridPack S.A.",'Dataset Limpio'!X2:X2001,"VERDADERO")/COUNTIF('Dataset Limpio'!F2:F2001,"MadridPack S.A."),0) -> 0.5025641 | F42: =AVERAGEIF('Dataset Limpio'!F2:F2001,"MadridPack S.A.",'Dataset Limpio'!V2:V2001) -> 1.774359 | G42: =IFERROR(COUNTIFS('Dataset Limpio'!F2:F2001,"MadridPack S.A.",'Dataset Limpio'!AB2:AB2001,"VERDADERO")/COUNTIF('Dataset Limpio'!F2:F2001,"MadridPack S.A."),0) -> 0.54358974 | H42: =AVERAGEIF('Dataset Limpio'!F2:F2001,"MadridPack S.A.",'Dataset Limpio'!S2:S2001) -> 15.164103 | I42: =SUMIF('Dataset Limpio'!F2:F2001,"MadridPack S.A.",'Dataset Limpio'!Q2:Q2001) -> 2350290.1 | J42: =IFERROR(SUMIF('Dataset Limpio'!F2:F2001,"MadridPack S.A.",'Dataset Limpio'!Q2:Q2001)/SUMIF('Dataset Limpio'!F2:F2001,"MadridPack S.A.",'Dataset Limpio'!P2:P2001),0) -> 0.048071901
B43: TransEuro Logistics | C43: =COUNTIF('Dataset Limpio'!F2:F2001,"TransEuro Logistics") -> 192 | D43: =SUMIF('Dataset Limpio'!F2:F2001,"TransEuro Logistics",'Dataset Limpio'!P2:P2001) -> 52666077 | E43: =IFERROR(COUNTIFS('Dataset Limpio'!F2:F2001,"TransEuro Logistics",'Dataset Limpio'!X2:X2001,"VERDADERO")/COUNTIF('Dataset Limpio'!F2:F2001,"TransEuro Logistics"),0) -> 0.46354167 | F43: =AVERAGEIF('Dataset Limpio'!F2:F2001,"TransEuro Logistics",'Dataset Limpio'!V2:V2001) -> 2.1979167 | G43: =IFERROR(COUNTIFS('Dataset Limpio'!F2:F2001,"TransEuro Logistics",'Dataset Limpio'!AB2:AB2001,"VERDADERO")/COUNTIF('Dataset Limpio'!F2:F2001,"TransEuro Logistics"),0) -> 0.53645833 | H43: =AVERAGEIF('Dataset Limpio'!F2:F2001,"TransEuro Logistics",'Dataset Limpio'!S2:S2001) -> 15.375 | I43: =SUMIF('Dataset Limpio'!F2:F2001,"TransEuro Logistics",'Dataset Limpio'!Q2:Q2001) -> 2684116.1 | J43: =IFERROR(SUMIF('Dataset Limpio'!F2:F2001,"TransEuro Logistics",'Dataset Limpio'!Q2:Q2001)/SUMIF('Dataset Limpio'!F2:F2001,"TransEuro Logistics",'Dataset Limpio'!P2:P2001),0) -> 0.0509648
B44: Iberian Freight Co. | C44: =COUNTIF('Dataset Limpio'!F2:F2001,"Iberian Freight Co.") -> 186 | D44: =SUMIF('Dataset Limpio'!F2:F2001,"Iberian Freight Co.",'Dataset Limpio'!P2:P2001) -> 44190510 | E44: =IFERROR(COUNTIFS('Dataset Limpio'!F2:F2001,"Iberian Freight Co.",'Dataset Limpio'!X2:X2001,"VERDADERO")/COUNTIF('Dataset Limpio'!F2:F2001,"Iberian Freight Co."),0) -> 0.46236559 | F44: =AVERAGEIF('Dataset Limpio'!F2:F2001,"Iberian Freight Co.",'Dataset Limpio'!V2:V2001) -> 2.1451613 | G44: =IFERROR(COUNTIFS('Dataset Limpio'!F2:F2001,"Iberian Freight Co.",'Dataset Limpio'!AB2:AB2001,"VERDADERO")/COUNTIF('Dataset Limpio'!F2:F2001,"Iberian Freight Co."),0) -> 0.66129032 | H44: =AVERAGEIF('Dataset Limpio'!F2:F2001,"Iberian Freight Co.",'Dataset Limpio'!S2:S2001) -> 14.822581 | I44: =SUMIF('Dataset Limpio'!F2:F2001,"Iberian Freight Co.",'Dataset Limpio'!Q2:Q2001) -> 2187540.7 | J44: =IFERROR(SUMIF('Dataset Limpio'!F2:F2001,"Iberian Freight Co.",'Dataset Limpio'!Q2:Q2001)/SUMIF('Dataset Limpio'!F2:F2001,"Iberian Freight Co.",'Dataset Limpio'!P2:P2001),0) -> 0.049502499
B45: Global Parts S.L. | C45: =COUNTIF('Dataset Limpio'!F2:F2001,"Global Parts S.L.") -> 209 | D45: =SUMIF('Dataset Limpio'!F2:F2001,"Global Parts S.L.",'Dataset Limpio'!P2:P2001) -> 48417095 | E45: =IFERROR(COUNTIFS('Dataset Limpio'!F2:F2001,"Global Parts S.L.",'Dataset Limpio'!X2:X2001,"VERDADERO")/COUNTIF('Dataset Limpio'!F2:F2001,"Global Parts S.L."),0) -> 0.44019139 | F45: =AVERAGEIF('Dataset Limpio'!F2:F2001,"Global Parts S.L.",'Dataset Limpio'!V2:V2001) -> 2.1435407 | G45: =IFERROR(COUNTIFS('Dataset Limpio'!F2:F2001,"Global Parts S.L.",'Dataset Limpio'!AB2:AB2001,"VERDADERO")/COUNTIF('Dataset Limpio'!F2:F2001,"Global Parts S.L."),0) -> 0.56937799 | H45: =AVERAGEIF('Dataset Limpio'!F2:F2001,"Global Parts S.L.",'Dataset Limpio'!S2:S2001) -> 14.779904 | I45: =SUMIF('Dataset Limpio'!F2:F2001,"Global Parts S.L.",'Dataset Limpio'!Q2:Q2001) -> 2494067.3 | J45: =IFERROR(SUMIF('Dataset Limpio'!F2:F2001,"Global Parts S.L.",'Dataset Limpio'!Q2:Q2001)/SUMIF('Dataset Limpio'!F2:F2001,"Global Parts S.L.",'Dataset Limpio'!P2:P2001),0) -> 0.051512121
B46: Almería Fresh Supply | C46: =COUNTIF('Dataset Limpio'!F2:F2001,"Almería Fresh Supply") -> 184 | D46: =SUMIF('Dataset Limpio'!F2:F2001,"Almería Fresh Supply",'Dataset Limpio'!P2:P2001) -> 43670911 | E46: =IFERROR(COUNTIFS('Dataset Limpio'!F2:F2001,"Almería Fresh Supply",'Dataset Limpio'!X2:X2001,"VERDADERO")/COUNTIF('Dataset Limpio'!F2:F2001,"Almería Fresh Supply"),0) -> 0.38586957 | F46: =AVERAGEIF('Dataset Limpio'!F2:F2001,"Almería Fresh Supply",'Dataset Limpio'!V2:V2001) -> 2.8152174 | G46: =IFERROR(COUNTIFS('Dataset Limpio'!F2:F2001,"Almería Fresh Supply",'Dataset Limpio'!AB2:AB2001,"VERDADERO")/COUNTIF('Dataset Limpio'!F2:F2001,"Almería Fresh Supply"),0) -> 0.61413043 | H46: =AVERAGEIF('Dataset Limpio'!F2:F2001,"Almería Fresh Supply",'Dataset Limpio'!S2:S2001) -> 15.684783 | I46: =SUMIF('Dataset Limpio'!F2:F2001,"Almería Fresh Supply",'Dataset Limpio'!Q2:Q2001) -> 2095372.9 | J46: =IFERROR(SUMIF('Dataset Limpio'!F2:F2001,"Almería Fresh Supply",'Dataset Limpio'!Q2:Q2001)/SUMIF('Dataset Limpio'!F2:F2001,"Almería Fresh Supply",'Dataset Limpio'!P2:P2001),0) -> 0.047980975
...

Sheet Analisis
A3: Cuenta de Cantidad | B3: Suma de Valor_Total_EUR | D3: Suma de Coste_Transporte_EUR | F3: Promedio de Lead_Time_Días
A4: 93 | B4: 26940862 | D4: 1395976.2 | F4: 15.666667
D7: Cuenta de ID_Pedido | E7: Etiquetas de columna | R7: Promedio de OTIF (%)
D8: Etiquetas de fila | E8: LogiTech Supply S.L. | F8: Total general | R8: 0.4857418
D9: 2024 | E9: 93 | F9: 93
A10: Etiquetas de fila | B10: Cuenta de ID_Pedido | D10: 1 | E10: 7 | F10: 7 | R10: Año_Pedido | S10: 2024
A11: En almacén | B11: 23 | D11: 2 | E11: 10 | F11: 10
A12: Entregado | B12: 42 | D12: 3 | E12: 7 | F12: 7 | R12: Etiquetas de fila | S12: Cuenta de Incidencias
A13: Retrasado | B13: 28 | D13: 4 | E13: 7 | F13: 7 | R13: FALSO | S13: 39
A14: Total general | B14: 93 | D14: 5 | E14: 7 | F14: 7 | R14: VERDADERO | S14: 54
D15: 6 | E15: 7 | F15: 7 | R15: Total general | S15: 93
D16: 7 | E16: 6 | F16: 6
D17: 8 | E17: 8 | F17: 8
D18: 9 | E18: 4 | F18: 4
D19: 10 | E19: 10 | F19: 10 | R19: Suma de Valor_Total_EUR | S19: Etiquetas de columna
D20: 11 | E20: 10 | F20: 10 | R20: Etiquetas de fila | S20: LogiTech Supply S.L. | T20: Total general
D21: 12 | E21: 10 | F21: 10 | R21: 2024 | S21: 26940862 | T21: 26940862
D22: Total general | E22: 93 | F22: 93 | R22: 1 | S22: 1137312.2 | T22: 1137312.2
R23: 2 | S23: 7095420.4 | T23: 7095420.4
R24: 3 | S24: 1793676.4 | T24: 1793676.4
R25: 4 | S25: 1788111.9 | T25: 1788111.9
R26: 5 | S26: 3248778.5 | T26: 3248778.5
R27: 6 | S27: 1026944.3 | T27: 1026944.3
R28: 7 | S28: 859726.26 | T28: 859726.26
R29: 8 | S29: 2553081.1 | T29: 2553081.1
R30: 9 | S30: 613544.34 | T30: 613544.34
R31: 10 | S31: 2542477.3 | T31: 2542477.3
R32: 11 | S32: 2197500 | T32: 2197500
R33: 12 | S33: 2084289.3 | T33: 2084289.3
R34: Total general | S34: 26940862 | T34: 26940862

Sheet Dashboard
